Workbook

Sheet Today
B2: Today's Practice | E2: =Settings!$B$8-TODAY()
B3: =TEXT(TODAY(),"dddd, d mmmm yyyy") | E3: days to placements
B5: Progress | D5: Done | E5: Total
B6: LeetCode | C6: =SPARKLINE(D6/E6,{"charttype","bar";"max",1;"color1","#1D4ED8";"empty","zero"}) | D6: =COUNTIFS(Plan!$C$2:$C$625,"LeetCode",Plan!$G$2:$G$625,TRUE) | E6: =COUNTIF(Plan!$C$2:$C$625,"LeetCode")
B7: SQL | C7: =SPARKLINE(D7/E7,{"charttype","bar";"max",1;"color1","#1D4ED8";"empty","zero"}) | D7: =COUNTIFS(Plan!$C$2:$C$625,"SQL",Plan!$G$2:$G$625,TRUE) | E7: =COUNTIF(Plan!$C$2:$C$625,"SQL")
B8: Codeforces | C8: =SPARKLINE(D8/E8,{"charttype","bar";"max",1;"color1","#1D4ED8";"empty","zero"}) | D8: =COUNTIFS(Plan!$C$2:$C$625,"Codeforces",Plan!$G$2:$G$625,TRUE) | E8: =COUNTIF(Plan!$C$2:$C$625,"Codeforces")
B9: Solved today | D9: =COUNTIF(Plan!$H$2:$H$625,TODAY())
B11: ▶ Do these today | C11: Tick them in the Plan tab. Finish early? Keep going in Plan: tomorrow's problems slide up.
B12: Track | C12: Problem (click to open) | D12: Level | E12: Phase
B13: =ARRAYFORMULA(IF(H13:H24="","",H13:H24)) | C13: =ARRAYFORMULA(IF(K13:K24="","",HYPERLINK(IF(LEFT(K13:K24,4)="http",K13:K24,"https://leetcode.com/problems/"&K13:K24&"/"),I13:I24))) | D13: =ARRAYFORMULA(IF(J13:J24="","",J13:J24)) | E13: =IFERROR(INDEX(Plan!F2:F625,MATCH("▶ Today",Plan!B2:B625,0)),"") | H13: =IFERROR(ARRAY_CONSTRAIN(FILTER({Plan!C2:C625,Plan!D2:D625,Plan!E2:E625,Plan!L2:L625},Plan!B2:B625="▶ Today"),12,4),"🎉 All done for today. Do extra in Plan if you have time.")
B26: ↻ Revisit today (redo from memory) | C26: Problems you needed help on, coming back 3, 7 and 21 days after you solved them.
B27: Track | C27: Problem (click to open) | D27: Help used | E27: Solved on
B28: =ARRAYFORMULA(IF(H28:H40="","",H28:H40)) | C28: =ARRAYFORMULA(IF(K28:K40="","",HYPERLINK(IF(LEFT(K28:K40,4)="http",K28:K40,"https://leetcode.com/problems/"&K28:K40&"/"),I28:I40))) | D28: =ARRAYFORMULA(IF(J28:J40="","",J28:J40)) | H28: =IFERROR(ARRAY_CONSTRAIN(FILTER({Plan!C2:C625,Plan!D2:D625,Plan!I2:I625,Plan!L2:L625},((Plan!I2:I625="Hint")+(Plan!I2:I625="Editorial"))*((IFERROR(TODAY()-Plan!H2:H625,0)=3)+(IFERROR(TODAY()-Plan!H2:H625,0)=7)+(IFERROR(TODAY()-Plan!H2:H625,0)=21))),13,4),"Nothing to revisit today.")

Sheet Plan
A1: Due | B1: Status | C1: Track | D1: Problem (click to open) | E1: Level | F1: Phase | G1: Done | H1: Done on | I1: Needed help? | J1: Key insight (1 line) | K1: Topic (spoiler) | L1: url | M1: title | N1: slot | O1: quota
A2: =ARRAYFORMULA(IF(C2:C625="","",IF(G2:G625=TRUE,H2:H625,IF(C2:C625="Codeforces",IF(((TODAY()-WEEKDAY(TODAY(),2)+1)+5+7*INT(N2:N625/O2:O625))<TODAY(),TODAY(),((TODAY()-WEEKDAY(TODAY(),2)+1)+5+7*INT(N2:N625/O2:O625))),TODAY()+INT(N2:N625/O2:O625))))) | B2: =ARRAYFORMULA(IF(C2:C625="","",IF(G2:G625=TRUE,"✓ Done",IF(A2:A625=TODAY(),"▶ Today",IF(A2:A625=TODAY()+1,"Tomorrow",TEXT(A2:A625,"ddd, dd mmm")))))) | C2: LeetCode | D2: =ARRAYFORMULA(IF(L2:L625="","",HYPERLINK(IF(LEFT(L2:L625,4)="http",L2:L625,"https://leetcode.com/problems/"&L2:L625&"/"),IF(M2:M625="",PROPER(SUBSTITUTE(L2:L625,"-"," ")),M2:M625)))) | E2: Medium | F2: =ARRAYFORMULA(IF(C2:C625="","",IF(ROW(C2:C625)<220,"1 · Unseen Mediums",IF(ROW(C2:C625)<427,"2 · Medium-Hard",IF(ROW(C2:C625)<577,"3 · OA Simulation","4 · Revision"))))) | H2: =IF(G2=TRUE,IF(H2="",TODAY(),H2),"") | K2: Backtracking, Tree | L2: path-sum-ii | M2: Path Sum II | N2: =ARRAYFORMULA(IF(G2:G625=TRUE,"",MMULT((C2:C625=TRANSPOSE(C2:C625))*(ROW(C2:C625)>=TRANSPOSE(ROW(C2:C625)))*(TRANSPOSE(G2:G625)<>TRUE),SIGN(ROW(C2:C625)))-1+IF(C2:C625="Codeforces",COUNTIFS(C2:C625,"Codeforces",H2:H625,">="&(TODAY()-WEEKDAY(TODAY(),2)+1)),MMULT((C2:C625=TRANSPOSE(C2:C625))*IFERROR(TRANSPOSE(H2:H625)=TODAY(),FALSE),SIGN(ROW(C2:C625)))))) | O2: =ARRAYFORMULA(IF(C2:C625="LeetCode",Settings!$B$4,IF(C2:C625="SQL",Settings!$B$5,Settings!$B$6)))
C3: LeetCode | E3: Medium | H3: =IF(G3=TRUE,IF(H3="",TODAY(),H3),"") | K3: Array, Hash Table | L3: count-triplets-that-can-form-two-arrays-of-equal-xor
C4: SQL | E4: Easy | H4: =IF(G4=TRUE,IF(H4="",TODAY(),H4),"") | K4: SQL | L4: combine-two-tables
C5: LeetCode | E5: Medium | H5: =IF(G5=TRUE,IF(H5="",TODAY(),H5),"") | K5: Array, Hash Table | L5: longest-well-performing-interval
C6: LeetCode | E6: Medium | H6: =IF(G6=TRUE,IF(H6="",TODAY(),H6),"") | K6: Array, Stack | L6: construct-binary-search-tree-from-preorder-traversal
C7: SQL | E7: Easy | H7: =IF(G7=TRUE,IF(H7="",TODAY(),H7),"") | K7: SQL | L7: rising-temperature
C8: Codeforces | E8: CF 1200 | H8: =IF(G8=TRUE,IF(H8="",TODAY(),H8),"") | K8: greedy | L8: https://codeforces.com/problemset?order=BY_SOLVED_DESC&tags=greedy,1200-1200 | M8: Most-solved unsolved: greedy · 1200
C9: Codeforces | E9: CF 1300 | H9: =IF(G9=TRUE,IF(H9="",TODAY(),H9),"") | K9: constructive algorithms | L9: https://codeforces.com/problemset?order=BY_SOLVED_DESC&tags=constructive%20algorithms,1300-1300 | M9: Most-solved unsolved: constructive algorithms · 1300
C10: LeetCode | E10: Medium | H10: =IF(G10=TRUE,IF(H10="",TODAY(),H10),"") | K10: Array, Hash Table | L10: construct-binary-tree-from-preorder-and-postorder-traversal
C11: LeetCode | E11: Medium | H11: =IF(G11=TRUE,IF(H11="",TODAY(),H11),"") | K11: Array, Sliding Window | L11: grumpy-bookstore-owner
C12: SQL | E12: Easy | H12: =IF(G12=TRUE,IF(H12="",TODAY(),H12),"") | K12: SQL | L12: customer-who-visited-but-did-not-make-any-transactions
C13: LeetCode | E13: Medium | H13: =IF(G13=TRUE,IF(H13="",TODAY(),H13),"") | K13: Linked List, Divide and Conquer | L13: convert-sorted-list-to-binary-search-tree
C14: LeetCode | E14: Medium | H14: =IF(G14=TRUE,IF(H14="",TODAY(),H14),"") | K14: Array, Two Pointers | L14: valid-triangle-number
C15: SQL | E15: Easy | H15: =IF(G15=TRUE,IF(H15="",TODAY(),H15),"") | K15: SQL | L15: recyclable-and-low-fat-products
C16: LeetCode | E16: Medium | H16: =IF(G16=TRUE,IF(H16="",TODAY(),H16),"") | K16: Hash Table, String | L16: minimum-number-of-steps-to-make-two-strings-anagram
C17: LeetCode | E17: Medium | H17: =IF(G17=TRUE,IF(H17="",TODAY(),H17),"") | K17: Hash Table, Tree | L17: all-nodes-distance-k-in-binary-tree
C18: SQL | E18: Easy | H18: =IF(G18=TRUE,IF(H18="",TODAY(),H18),"") | K18: SQL | L18: big-countries
C19: LeetCode | E19: Medium | H19: =IF(G19=TRUE,IF(H19="",TODAY(),H19),"") | K19: Hash Table, Tree | L19: most-frequent-subtree-sum
C20: LeetCode | E20: Medium | H20: =IF(G20=TRUE,IF(H20="",TODAY(),H20),"") | K20: Math, Bit Manipulation | L20: k-th-symbol-in-grammar
C21: SQL | E21: Easy | H21: =IF(G21=TRUE,IF(H21="",TODAY(),H21),"") | K21: SQL | L21: employees-earning-more-than-their-managers
... C30: SQL | E30: Easy | H30: =IF(G30=TRUE,IF(H30="",TODAY(),H30),"") | K30: SQL | L30: find-customer-referee
C31: Codeforces | E31: CF 1200 | H31: =IF(G31=TRUE,IF(H31="",TODAY(),H31),"") | K31: math | L31: https://codeforces.com/problemset?order=BY_SOLVED_DESC&tags=math,1200-1200 | M31: Most-solved unsolved: math · 1200
C32: Codeforces | E32: CF 1300 | H32: =IF(G32=TRUE,IF(H32="",TODAY(),H32),"") | K32: implementation | L32: https://codeforces.com/problemset?order=BY_SOLVED_DESC&tags=implementation,1300-1300 | M32: Most-solved unsolved: implementation · 1300
C33: LeetCode | E33: Medium | H33: =IF(G33=TRUE,IF(H33="",TODAY(),H33),"") | K33: Math, Binary Search | L33: maximum-value-at-a-given-index-in-a-bounded-array
C34: LeetCode | E34: Medium | H34: =IF(G34=TRUE,IF(H34="",TODAY(),H34),"") | K34: Math, String | L34: number-of-substrings-with-only-1s
C35: SQL | E35: Easy | H35: =IF(G35=TRUE,IF(H35="",TODAY(),H35),"") | K35: SQL | L35: average-time-of-process-per-machine
C36: LeetCode | E36: Medium | H36: =IF(G36=TRUE,IF(H36="",TODAY(),H36),"") | K36: Array, Stack | L36: minimum-deletions-to-make-array-beautiful
C37: LeetCode | E37: Medium | H37: =IF(G37=TRUE,IF(H37="",TODAY(),H37),"") | K37: Math | L37: angle-between-hands-of-a-clock
C38: SQL | E38: Easy | H38: =IF(G38=TRUE,IF(H38="",TODAY(),H38),"") | K38: SQL | L38: duplicate-emails
C39: LeetCode | E39: Medium | H39: =IF(G39=TRUE,IF(H39="",TODAY(),H39),"") | K39: String, Stack | L39: score-of-parentheses
C40: LeetCode | E40: Medium | H40: =IF(G40=TRUE,IF(H40="",TODAY(),H40),"") | K40: Divide and Conquer, Greedy | L40: balance-a-binary-search-tree
C41: SQL | E41: Easy | H41: =IF(G41=TRUE,IF(H41="",TODAY(),H41),"") | K41: SQL | L41: article-views-i | M41: Article Views I
C42: LeetCode | E42: Medium | H42: =IF(G42=TRUE,IF(H42="",TODAY(),H42),"") | K42: Tree, Depth-First Search | L42: longest-univalue-path
C43: LeetCode | E43: Medium | H43: =IF(G43=TRUE,IF(H43="",TODAY(),H43),"") | K43: Array, Two Pointers | L43: rearrange-array-elements-by-sign
C44: SQL | E44: Easy | H44: =IF(G44=TRUE,IF(H44="",TODAY(),H44),"") | K44: SQL | L44: delete-duplicate-emails
C45: LeetCode | E45: Medium | H45: =IF(G45=TRUE,IF(H45="",TODAY(),H45),"") | K45: Array, Math | L45: minimum-time-difference
C46: LeetCode | E46: Medium | H46: =IF(G46=TRUE,IF(H46="",TODAY(),H46),"") | K46: Tree, Depth-First Search | L46: maximum-difference-between-node-and-ancestor
C47: SQL | E47: Easy | H47: =IF(G47=TRUE,IF(H47="",TODAY(),H47),"") | K47: SQL | L47: replace-employee-id-with-the-unique-identifier
C48: LeetCode | E48: Medium | H48: =IF(G48=TRUE,IF(H48="",TODAY(),H48),"") | K48: Array, Greedy | L48: increasing-triplet-subsequence
...

Sheet How to Use
B2: How to use this tracker
B4: One-time setup (1 minute)
B5: 1 | C5: Go to the Plan tab, click the column letter G (Done), then Insert → Checkbox.
B6: 2 | C6: File → Settings → Calculation → Iterative calculation: ON. This lets 'Done on' remember the day you ticked a box.
B7: Every day
B8: 1 | C8: Open the Today tab. It lists today's minimum: 2 LeetCode + 1 SQL (+2 Codeforces on Saturdays).
B9: 2 | C9: Click a problem name to open it on LeetCode / Codeforces. Topic tags are hidden on purpose.
B10: 3 | C10: When solved, tick it in the Plan tab (green rows = today) and pick Solo / Hint / Editorial.
B11: 4 | C11: Got time? Keep ticking the next rows in Plan. Everything after slides one step earlier, so tomorrow still has a full minimum.
B12: 5 | C12: Missed a day? Nothing piles up. Unfinished problems simply roll to today.
B13: 6 | C13: Problems marked Hint or Editorial come back on the Today tab after 3, 7 and 21 days.
B14: Tips
B15: • | C15: Topic (spoiler) column: the text is hidden. Click the cell and read it in the formula bar after you solve.
B16: • | C16: Change daily counts in the Settings tab. Roadmap tab has the phase plan.
B17: • | C17: Already solved a problem? Tick it anyway and mark Solo, or replace the row with a new one.

Sheet Roadmap
B2: Roadmap · Oct 2026 → May 2027
B4: Phase | C4: Dates | D4: LeetCode | E4: Codeforces (Sat) | F4: SQL | G4: Goal
B5: 1 · Unseen Mediums | C5: Oct 23 – Dec 27 | D5: Random Mediums from the most-asked OA topics, tags hidden. No DP yet. | E5: 1200–1300 | F5: Easy → Medium | G5: Solve a random Medium solo in < 30 min
B6: 2 · Medium-Hard | C6: Dec 28 – Feb 28 | D6: 70% Medium / 30% Hard. Common DP patterns start (about 1 in 4). | E6: 1400–1500 | F6: Medium | G6: Hards feel approachable
B7: 3 · OA Simulation | C7: Mar 1 – Apr 15 | D7: 50% Medium / 50% Hard. Twice a week, do 3 in 90 min with no hints. | E7: 1500–1700 | F7: Medium/Hard, then round 2 | G7: Pass a 90-min OA mock
B8: 4 · Revision | C8: Apr 16 – May 1 | D8: Mediums plus the revisit queue. No new topics. | E8: 1600 | F8: Round 2 | G8: Calm and sharp
B10: Rules for every new problem
B11: 1. | C11: Read it and write down the constraints before thinking of an approach.
B12: 2. | C12: Think for 25 min before any hint: brute force → why it is slow → what to optimise.
B13: 3. | C13: Write a one-line key insight. That line is what you revise.
B14: 4. | C14: Sunday: LeetCode Weekly Contest (8:00 AM IST). Upsolve what you missed.

Sheet Settings
A1: Settings
A2: Change the blue numbers. The whole schedule re-flows instantly.
A4: LeetCode problems per day | B4: 2 | C4: Your daily minimum
A5: SQL problems per day | B5: 1
A6: Codeforces problems per week (Saturday) | B6: 2
A8: Placement date | B8: 46508
A10: Problem sources: LeetCode problems are free (non-premium), well-liked, and exclude the NeetCode 150/250 lists you have likely already done. SQL = every free LeetCode database problem, then a second round of re-solving. Codeforces links open the problemset filtered by topic and rating; solve the first one you haven't solved.
